Workbook

Sheet Inequação FEPAM
B1: PREENCHER ABAIXO NO AZUL
B3: Fonte da Informação | C3: Parâmetro | D3: Lançamento Existente
B4: Estudo ou Adotar | C4: Vazão (L/s) | D4: 155 | E4: 20 | F4: 20
B5: SEMA - Verificar bacia | C5: Classe | D5: 2 | E5: 1 | F5: 1
B6: Site que calcula área a partir de Exutório | C6: Area da bacia do ponto (km²) | D6: 633.8 | E6: 5 | F6: 2400
B7: NOTA TÉCNICA nº 004/2021/DIPLA/DRHS | C7: Vazão Específica se < 10km²(m³/s.km²) | D7: 0.00404 | E7: 0.002 | F7: 0.002
B8: Identificar UPG em SIOUT RS | C8: Vazão Específica se > 10km²(m³/s.km²) | D8: 0.0074 | E8: 0.001 | F8: 0.001
B9: Se necessário, alterar padrões de DBO e Coliformes aqui --> | C9: DBO - Tratamento adotado (mg/L) | D9: =VLOOKUP(D29,'Inequação FEPAM'!$B$41:$G$46,$A$16,FALSE) -> 40 | E9: =VLOOKUP(E29,'Inequação FEPAM'!$B$41:$G$46,$A$16,FALSE) -> 70 | F9: =VLOOKUP(F29,'Inequação FEPAM'!$B$41:$G$46,$A$16,FALSE) -> 70
C10: eColi - Tratamento adotado (NMP/100mL) | D10: =VLOOKUP(D29,'Inequação FEPAM'!$B$41:$G$46,$A$22,FALSE) -> 1000 | E10: =VLOOKUP(E29,'Inequação FEPAM'!$B$41:$G$46,$A$22,FALSE) -> 100000 | F10: =VLOOKUP(F29,'Inequação FEPAM'!$B$41:$G$46,$A$22,FALSE) -> 100000
B12: AUTOMÁTICO ABAIXO
H14: =D3 -> Lançamento Existente
A15: Índice Procv | B15: Parâmetro | D15: =D3 -> Lançamento Existente | E15: =E3 -> 0 | F15: =F3 -> 0 | H15: Parâmetro | I15: Vazões (L/s) | K15: Inequação | L15: Concentrações (mg/L, NMP/100ml) | O15: Parâmetro | P15: DBO | Q15: Coliformes
A16: 4 | B16: DBO | C16: Padrão de Emissão (mg/L) | D16: =VLOOKUP(D29,'Inequação FEPAM'!$B$41:$G$46,$A$16,FALSE) -> 40 | E16: =VLOOKUP(E29,'Inequação FEPAM'!$B$41:$G$46,$A$16,FALSE) -> 70 | F16: =VLOOKUP(F29,'Inequação FEPAM'!$B$41:$G$46,$A$16,FALSE) -> 70 | O16: Qchr (sobrescrever) | P16: =J17&" L/s" -> 4690,12 L/s
C17: Padrão de Emissão ADOTADO(mg/L) | D17: =MIN(D16,D9) -> 40 | E17: =MIN(E16,E9) -> 70 | F17: =MIN(F16,F9) -> 70 | H17: DBO | I17: Qchr | J17: =$D$26 -> 4690.12 | K17: =CONCATENATE(ROUND($D$30,2),IF($D$30>$D$19," > ", " < "),$D$19) -> 30,26 > 8 | L17: =D17 -> 40 | M17: Padrão de lançamento | O17: Qe (sobrescrever) | P17: =J18&" L/s" -> 155 L/s
C18: Concentração na classe (mg/L) | D18: =VLOOKUP('Inequação FEPAM'!D5,'Inequação FEPAM'!$B$50:$D$52,$A$19,FALSE) -> 5 | E18: =VLOOKUP('Inequação FEPAM'!E5,'Inequação FEPAM'!$B$50:$D$52,$A$19,FALSE) -> 3 | F18: =VLOOKUP('Inequação FEPAM'!F5,'Inequação FEPAM'!$B$50:$D$52,$A$19,FALSE) -> 3 | I18: Qe | J18: =$D$27 -> 155 | L18: =$D$18 -> 5 | M18: Classe do CHR | O18: Padrão de Emissão | P18: =L17&" mg/L" -> 40 mg/L | Q18: =L19&" NPM/100mL" -> 1000 NPM/100mL
A19: 2 | C19: [Padrão]/[Classe] | D19: =ROUND(D9/D18,2) -> 8 | E19: =ROUND(E9/E18,2) -> 23.33 | F19: =ROUND(F9/F18,2) -> 23.33 | H19: Coliformes Termotolerates | I19: Qchr | J19: =$D$26 -> 4690.12 | K19: =CONCATENATE(ROUND($D$30,2),IF($D$30>$D$23," > ", " < "),$D$23) -> 30,26 > 1 | L19: =D21 -> 1000 | M19: Padrão de lançamento | O19: Concentração na Classe | P19: =L18&" mg/L" -> 5 mg/L | Q19: =L20&" NPM/100mL" -> 1000 NPM/100mL
B20: Coliformes | C20: Padrão de Emissão (NMP/100mL) | D20: =VLOOKUP(D29,'Inequação FEPAM'!$B$41:$G$46,$A$22,FALSE) -> 1000 | E20: =VLOOKUP(E29,'Inequação FEPAM'!$B$41:$G$46,$A$22,FALSE) -> 100000 | F20: =VLOOKUP(F29,'Inequação FEPAM'!$B$41:$G$46,$A$22,FALSE) -> 100000 | I20: Qe | J20: =$D$27 -> 155 | L20: =$D$22 -> 1000 | M20: Classe do CHR
C21: Padrão de Emissão ADOTADO (NMP/100mL) | D21: =MIN(D20,D10) -> 1000 | E21: =MIN(E20,E10) -> 100000 | F21: =MIN(F20,F10) -> 100000
A22: 5 | C22: Concentração na classe (NMP/100mL) | D22: =VLOOKUP('Inequação FEPAM'!D5,'Inequação FEPAM'!$B$50:$D$52,$A$24,FALSE) -> 1000 | E22: =VLOOKUP('Inequação FEPAM'!E5,'Inequação FEPAM'!$B$50:$D$52,$A$24,FALSE) -> 200 | F22: =VLOOKUP('Inequação FEPAM'!F5,'Inequação FEPAM'!$B$50:$D$52,$A$24,FALSE) -> 200 | H22: =E3 -> 0
C23: [Padrão]/[Classe] | D23: =ROUND(D10/D22,2) -> 1 | E23: =ROUND(E10/E22,2) -> 500 | F23: =ROUND(F10/F22,2) -> 500 | H23: Parâmetro | I23: Vazões (L/s) | K23: Inequação | L23: Concentrações (mg/L, NMP/100ml) | O23: Parâmetro | P23: DBO | Q23: Coliformes
A24: 3 | B24: Corpo Hídrico | C24: Area da bacia do ponto (km²) | D24: =D6 -> 633.8 | E24: =E6 -> 5 | F24: =F6 -> 2400 | O24: Qchr (sobrescrever) | P24: =J25&" L/s" -> 5 L/s
C25: Vazão Específica (m³/s.km²) | D25: =IF(D24<10,D7,D8) -> 0.0074 | E25: =IF(E24<10,E8,E7) -> 0.001 | F25: =IF(F24<10,F8,F7) -> 0.002 | H25: DBO | I25: Qchr | J25: =$E$26 -> 5 | K25: =CONCATENATE(ROUND($E$30,2),IF($E$30>$E$19," > ", " < "),$E$19) -> 0,25 < 23,33 | L25: =$E$17 -> 70 | M25: Padrão de lançamento | O25: Qe (sobrescrever) | P25: =J26&" L/s" -> 20 L/s
C26: Vazão do ponto de lançamento Qchr (L/s) | D26: =D24*D25*1000 -> 4690.12 | E26: =E24*E25*1000 -> 5 | F26: =F24*F25*1000 -> 4800 | I26: Qe | J26: =$E$27 -> 20 | L26: =$E$18 -> 3 | M26: Classe do CHR | O26: Padrão de Emissão | P26: =L25&" mg/L" -> 70 mg/L | Q26: =L27&" NPM/100mL" -> 100000 NPM/100mL
B27: Efluente | C27: Qe (L/s) | D27: =D4 -> 155 | E27: =E4 -> 20 | F27: =F4 -> 20 | H27: Coliformes Termotolerates | I27: Qchr | J27: =$E$26 -> 5 | K27: =CONCATENATE(ROUND($E$30,2),IF($E$30>$E$23," > ", " < "),$E$23) -> 0,25 < 500 | L27: =$E$21 -> 100000 | M27: Padrão de lançamento | O27: Concentração na Classe | P27: =L26&" mg/L" -> 3 mg/L | Q27: =L28&" NPM/100mL" -> 200 NPM/100mL
C28: Qe(m³/d) | D28: =D27*86.4 -> 13392 | E28: =E27*86.4 -> 1728 | F28: =F27*86.4 -> 1728 | I28: Qe | J28: =$E$27 -> 20 | L28: =$E$22 -> 200 | M28: Classe do CHR
C29: Faixa de Vazão | D29: =INDEX('Inequação FEPAM'!$B$41:$B$46, MATCH(D28, 'Inequação FEPAM'!$C$41:$C$46, 1)) -> 6 | E29: =INDEX('Inequação FEPAM'!$B$41:$B$46, MATCH(E28, 'Inequação FEPAM'!$C$41:$C$46, 1)) -> 4 | F29: =INDEX('Inequação FEPAM'!$B$41:$B$46, MATCH(F28, 'Inequação FEPAM'!$C$41:$C$46, 1)) -> 4
C30: Qchr/Qe | D30: =ROUND(D26/D27,2) -> 30.26 | E30: =ROUND(E26/E27,2) -> 0.25 | F30: =ROUND(F26/F27,2) -> 240 | H30: =F3 -> 0
H31: Parâmetro | I31: Vazões (L/s) | K31: Inequação | L31: Concentrações (mg/L, NMP/100ml) | O31: Parâmetro | P31: DBO | Q31: Coliformes
B32: Atende a inequação para DBO | D32: =D30>=D19 -> TRUE | E32: =E30>=E19 -> FALSE | F32: =F30>=F19 -> TRUE | O32: Qchr (sobrescrever) | P32: =J33&" L/s" -> 4800 L/s
B33: Atende a inequação e eColi | D33: =D30>=D23 -> TRUE | E33: =E30>=E23 -> FALSE | F33: =F30>=F23 -> FALSE | H33: DBO | I33: Qchr | J33: =$F$26 -> 4800 | K33: =CONCATENATE(ROUND($F$30,2),IF($F$30>$F$19," > ", " < "),$F$19) -> 240 > 23,33 | L33: =$F$17 -> 70 | M33: Padrão de lançamento | O33: Qe (sobrescrever) | P33: =J34&" L/s" -> 20 L/s
B34: Parâmetro limitante | D34: =IF(AND(D32=FALSE,D33=FALSE),"DBO e eColi",IF(AND(D32=TRUE,D33=FALSE),"eColi",IF(AND(D33=TRUE,D32=FALSE),"DBO","-"))) -> - | E34: =IF(AND(E32=FALSE,E33=FALSE),"DBO e eColi",IF(AND(E32=TRUE,E33=FALSE),"eColi",IF(AND(E33=TRUE,E32=FALSE),"DBO","-"))) -> DBO e eColi | F34: =IF(AND(F32=FALSE,F33=FALSE),"DBO e eColi",IF(AND(F32=TRUE,F33=FALSE),"eColi",IF(AND(F33=TRUE,F32=FALSE),"DBO","-"))) -> eColi | I34: Qe | J34: =$F$27 -> 20 | L34: =$F$18 -> 3 | M34: Classe do CHR | O34: Padrão de Emissão | P34: =L33&" mg/L" -> 70 mg/L | Q34: =L35&" NPM/100mL" -> 100000 NPM/100mL
H35: Coliformes Termotolerates | I35: Qchr | J35: =$F$26 -> 4800 | K35: =CONCATENATE(ROUND($F$30,2),IF($F$30>$F$23," > ", " < "),$F$23) -> 240 < 500 | L35: =$F$21 -> 100000 | M35: Padrão de lançamento | O35: Concentração na Classe | P35: =L34&" mg/L" -> 3 mg/L | Q35: =L36&" NPM/100mL" -> 200 NPM/100mL
A36: BASE DE DADOS ABAIXO | I36: Qe | J36: =$F$27 -> 20 | L36: =$F$22 -> 200 | M36: Classe do CHR
B38: Fonte: | C38: Resolução CONSEMA nº 355/2017
B39: Faixa de vazão do efluente (m³/d) | E39: (mg/L) | F39: Coliformes Termotolerantes
F40: NMP/ 100 mL | G40: Eficiência
B41: 1 | C41: 0 | D41: 199 | E41: 120 | F41: - | G41: -
B42: 2 | C42: 200 | D42: 499 | E42: 100 | F42: =10^6 -> 1000000 | G42: 0.9
B43: 3 | C43: 500 | D43: 999 | E43: 80 | F43: =10^5 -> 100000 | G43: 0.95
B44: 4 | C44: 1000 | D44: 1999 | E44: 70 | F44: =10^5 -> 100000 | G44: 0.95
...
